Workbook

Sheet Overview
B1: Meridian Fabrication Co. 13 - Week Rolling Cash Flow Forecast
B3: Purpose
B4: A treasury style 13-week cash forecast for a mid-size manufacturer. It converts weekly sales and purchases into cash receipts and payments using AR collection and AP payment lag curves, layers on payroll, opex, capex, debt service and taxes, tests the result against a minimum-cash covenant, stress-tests it with Best / Base / Worst scenarios, and measures how accurate past forecasts were.
B6: Headline results
B7: Cash today (Week 4 close) | C7: ='KPI Summary'!C4 -> 3267000
B8: Week 17 ending cash (Base) | C8: ='KPI Summary'!C5 -> 3440602.9
B9: Minimum covenant headroom (Base) | C9: ='KPI Summary'!C7 -> 2057387.7
B10: Worst-case minimum headroom | C10: ='KPI Summary'!D24 -> 631151.67
B12: Tab guide
B13: Dashboard | C13: KPI tiles and five charts: cash vs covenant, receipts vs disbursements, scenarios, disbursement mix, forecast accuracy.
B14: Assumptions | C14: Every input: AR/AP curves, sales & purchases drivers, seasonality, the payroll/opex/capex/debt/tax schedule, covenant minimum.
B15: Driver Build | C15: Weekly Sales and Purchases, Weeks 1-17 (4 closed actual + 13 forecast). Feeds the AR/AP lag calculation.
B16: Actuals | C16: Closed Weeks 1-4: what really happened, by cash-flow category.
B17: Live Model | C17: The current 13-week rolling forecast (Weeks 5-17), fully formula-driven.
B18: Scenario | C18: Best / Base / Worst 13-week cash, headroom and runway comparison, driven by receipts and disbursements levers.
B19: Variance Calc | C19: Actual vs. the prior forecast for each closed week, plus forecast accuracy by horizon (1-4 weeks out).
B20: Snapshot Log | C20: Append-only forecast history: every weekly 13-week forecast vintage plus every actual, stored as one long table. It is the data source for Variance Calc.
B21: KPI Summary | C21: One-page table of the headline numbers that the Dashboard displays.
B22: Chart Data | C22: Helper ranges that feed the Dashboard charts
B25: Colour key
B26: Blue text | C26: Hard-coded input
B27: Black text | C27: Formula
B28: Green text | C28: Link to another sheet
B29: Yellow fill | C29: Key assumption / scenario lever
B31: Data note
B32: All figures are synthetic, created for this portfolio project. No real company, customer, vendor or bank data is used. Curve shapes and seasonality are illustrative of a mid-size industrial manufacturer.

Sheet Dashboard
B1: Meridian Fabrication Co. - 13 Week Cash Forecast Dashboard
B2: ="As of Week "&Assumptions!$C$30&" close ("&TEXT(INDEX(Actuals!$C$3:$F$3,Assumptions!$C$30),"mmm d, yyyy")&") | Forecast Weeks 5–17 " -> As of Week 4 close (Sep 11, 2026) | Forecast Weeks 5–17
B4: Cash Today | E4: Week 17 Cash (Base) | H4: Min Headroom (Base) | K4: Min Headroom (Worst) | N4: Avg Weekly Net CF | Q4: 1-Wk Out Accuracy
B5: ='KPI Summary'!C4 -> 3267000 | E5: ='KPI Summary'!C5 -> 3440602.9 | H5: ='KPI Summary'!C7 -> 2057387.7 | K5: ='KPI Summary'!D24 -> 631151.67 | N5: ='KPI Summary'!C8 -> 13354.069 | Q5: ='KPI Summary'!C15 -> 0.061405835

Sheet Assumptions
B1: Meridian Fabrication Co. - 13-Week Rolling Cash Flow Forecast
B3: AR Collection Curve (% of a week's billings collected, by weeks after invoice)
B4: Weeks After Invoice | C4: % Collected
B5: Week 0 | C5: 0.08
B6: Week 1 | C6: 0.37
B7: Week 2 | C7: 0.28
B8: Week 3 | C8: 0.17
B9: Week 4 | C9: 0.08
B10: Bad Debt / Uncollectible | C10: 0.02
B11: Total | C11: =SUM(C5:C10) -> 1
B13: AP Payment Curve (% of a week's purchases paid, by weeks after purchase)
B14: Weeks After Purchase | C14: % Paid
B15: Week 0 | C15: 0.05
B16: Week 1 | C16: 0.2
B17: Week 2 | C17: 0.35
B18: Week 3 | C18: 0.3
B19: Week 4 | C19: 0.1
B20: Total | C20: =SUM(C15:C19) -> 1
B22: Sales & Purchases Drivers
B23: Base Weekly Sales (Week 1 anchor) | C23: 1000000
B24: Underlying Weekly Growth Rate | C24: 0.0025
B25: COGS / Purchases Ratio (% of Sales) | C25: 0.62
B27: Other Model Parameters
B28: Minimum Cash Covenant | C28: 1200000
B29: Beginning Cash Balance, Week 1 | C29: 2850000
B30: Current As-Of Week (last closed actual week) | C30: 4
B31: Forecast Horizon (weeks) | C31: 13
B33: Seasonality Index by Week (1.0 = normal week)
B34: Week # | C34: 1 | D34: 2 | E34: 3 | F34: 4 | G34: 5 | H34: 6 | I34: 7 | J34: 8 | K34: 9 | L34: 10 | M34: 11 | N34: 12 | O34: 13 | P34: 14 | Q34: 15 | R34: 16 | S34: 17
B35: Week Ending | C35: 46255 | D35: 46262 | E35: 46269 | F35: 46276 | G35: 46283 | H35: 46290 | I35: 46297 | J35: 46304 | K35: 46311 | L35: 46318 | M35: 46325 | N35: 46332 | O35: 46339 | P35: 46346 | Q35: 46353 | R35: 46360 | S35: 46367
B36: Seasonality Index | C36: 1 | D36: 1 | E36: 1.02 | F36: 1.02 | G36: 1.04 | H36: 1.05 | I36: 1.06 | J36: 1.05 | K36: 1.07 | L36: 1.04 | M36: 0.98 | N36: 0.93 | O36: 0.88 | P36: 0.8 | Q36: 0.62 | R36: 0.82 | S36: 0.75
B38: Disbursement & Other-Receipt Schedule - Current Live Forecast (Weeks 5–17)
B39: Week # | C39: 5 | D39: 6 | E39: 7 | F39: 8 | G39: 9 | H39: 10 | I39: 11 | J39: 12 | K39: 13 | L39: 14 | M39: 15 | N39: 16 | O39: 17
B40: Week Ending | C40: =G35 -> 46283 | D40: =H35 -> 46290 | E40: =I35 -> 46297 | F40: =J35 -> 46304 | G40: =K35 -> 46311 | H40: =L35 -> 46318 | I40: =M35 -> 46325 | J40: =N35 -> 46332 | ... O40: =S35 -> 46367
B41: Payroll | C41: 0 | D41: 318000 | E41: 0 | F41: 318000 | G41: 0 | H41: 318000 | I41: 0 | J41: 318000 | K41: 0 | L41: 318000 | M41: 0 | N41: 413000 | O41: 0
B42: Opex (incl. semi-annual insurance, Wk 11) | C42: 95000 | D42: 95000 | E42: 95000 | F42: 95000 | G42: 95000 | H42: 95000 | I42: 275000 | J42: 95000 | K42: 95000 | L42: 95000 | M42: 95000 | N42: 95000 | O42: 95000
B43: Capex (see notes below) | C43: 0 | D43: 0 | E43: 240000 | F43: 0 | G43: 0 | H43: 85000 | I43: 0 | J43: 0 | K43: 0 | L43: 150000 | M43: 0 | N43: 0 | O43: 0
B44: Debt Service (term loan P&I) | C44: 21000 | D44: 21000 | E44: 21000 | F44: 21000 | G44: 21000 | H44: 21000 | I44: 21000 | J44: 21000 | K44: 21000 | L44: 21000 | M44: 21000 | N44: 21000 | O44: 21000
B45: Taxes (Q4 estimated payment, Wk 12) | C45: 0 | D45: 0 | E45: 0 | F45: 0 | G45: 0 | H45: 0 | I45: 0 | J45: 310000 | K45: 0 | L45: 0 | M45: 0 | N45: 0 | O45: 0
B46: Other Receipts (interest income) | C46: 8000 | D46: 8000 | E46: 8000 | F46: 8000 | G46: 8000 | H46: 8000 | I46: 8000 | J46: 8000 | K46: 8000 | L46: 8000 | M46: 8000 | N46: 8000 | O46: 8000
...

Sheet Driver Build
B1: Sales & Purchases Driver Build (Weeks 1-17)
B3: Week # | C3: 1 | D3: 2 | E3: 3 | F3: 4 | G3: 5 | H3: 6 | I3: 7 | J3: 8 | K3: 9 | L3: 10 | M3: 11 | N3: 12 | O3: 13 | P3: 14 | Q3: 15 | R3: 16 | S3: 17
B4: Week Ending | C4: =Assumptions!C35 -> 46255 | D4: =Assumptions!D35 -> 46262 | E4: =Assumptions!E35 -> 46269 | F4: =Assumptions!F35 -> 46276 | G4: =Assumptions!G35 -> 46283 | H4: =Assumptions!H35 -> 46290 | I4: =Assumptions!I35 -> 46297 | J4: =Assumptions!J35 -> 46304 | ... S4: =Assumptions!S35 -> 46367
B5: Status | C5: =IF(C3<=Assumptions!$C$30,"Actual","Forecast") -> Actual | D5: =IF(D3<=Assumptions!$C$30,"Actual","Forecast") -> Actual | E5: =IF(E3<=Assumptions!$C$30,"Actual","Forecast") -> Actual | F5: =IF(F3<=Assumptions!$C$30,"Actual","Forecast") -> Actual | G5: =IF(G3<=Assumptions!$C$30,"Actual","Forecast") -> Forecast | H5: =IF(H3<=Assumptions!$C$30,"Actual","Forecast") -> Forecast | I5: =IF(I3<=Assumptions!$C$30,"Actual","Forecast") -> Forecast | J5: =IF(J3<=Assumptions!$C$30,"Actual","Forecast") -> Forecast | ... S5: =IF(S3<=Assumptions!$C$30,"Actual","Forecast") -> Forecast
B6: Sales | C6: 985000 | D6: 1010000 | E6: 1045000 | F6: 1020000 | G6: =Assumptions!$C$23*(1+Assumptions!$C$24)^(G3-1)*Assumptions!G36 -> 1050439.1 | H6: =Assumptions!$C$23*(1+Assumptions!$C$24)^(H3-1)*Assumptions!H36 -> 1063190.8 | I6: =Assumptions!$C$23*(1+Assumptions!$C$24)^(I3-1)*Assumptions!I36 -> 1075999.7 | J6: =Assumptions!$C$23*(1+Assumptions!$C$24)^(J3-1)*Assumptions!J36 -> 1068513.4 | K6: =Assumptions!$C$23*(1+Assumptions!$C$24)^(K3-1)*Assumptions!K36 -> 1091588.2 | L6: =Assumptions!$C$23*(1+Assumptions!$C$24)^(L3-1)*Assumptions!L36 -> 1063635.4 | M6: =Assumptions!$C$23*(1+Assumptions!$C$24)^(M3-1)*Assumptions!M36 -> 1004777.5 | N6: =Assumptions!$C$23*(1+Assumptions!$C$24)^(N3-1)*Assumptions!N36 -> 955897.1 | ... S6: =Assumptions!$C$23*(1+Assumptions!$C$24)^(S3-1)*Assumptions!S36 -> 780569.12
B7: Purchases (COGS) | C7: 610000 | D7: 640000 | E7: 615000 | F7: 655000 | G7: =G6*Assumptions!$C$25 -> 651272.22 | H7: =H6*Assumptions!$C$25 -> 659178.29 | I7: =I6*Assumptions!$C$25 -> 667119.82 | J7: =J6*Assumptions!$C$25 -> 662478.3 | K7: =K6*Assumptions!$C$25 -> 676784.68 | L7: =L6*Assumptions!$C$25 -> 659453.93 | M7: =M6*Assumptions!$C$25 -> 622962.03 | N7: =N6*Assumptions!$C$25 -> 592656.2 | ... S7: =S6*Assumptions!$C$25 -> 483952.85

Sheet Actuals
B1: Actuals - Closed Weeks 1 - 4
B2: Week # | C2: 1 | D2: 2 | E2: 3 | F2: 4
B3: Week Ending | C3: ='Driver Build'!C4 -> 46255 | D3: ='Driver Build'!D4 -> 46262 | E3: ='Driver Build'!E4 -> 46269 | F3: ='Driver Build'!F4 -> 46276
B5: Beginning Cash | C5: =Assumptions!$C$29 -> 2850000 | D5: =C19 -> 3069000 | E5: =D19 -> 2977000 | F5: =E19 -> 3372000
B6: AR Collections | C6: 905000 | D6: 935000 | E6: 1142000 | F6: 968000
B7: Other Receipts | C7: 8000 | D7: 8000 | E7: 8000 | F7: 8000
B8: Total Cash Receipts | C8: =SUM(C6:C7) -> 913000 | D8: =SUM(D6:D7) -> 943000 | E8: =SUM(E6:E7) -> 1150000 | F8: =SUM(F6:F7) -> 976000
B10: AP Payments | C10: 580000 | D10: 605000 | E10: 598000 | F10: 642000
B11: Payroll | C11: 0 | D11: 315000 | E11: 0 | F11: 322000
B12: Opex | C12: 93000 | D12: 94000 | E12: 91000 | F12: 96000
B13: Capex | C13: 0 | D13: 0 | E13: 45000 | F13: 0
B14: Debt Service | C14: 21000 | D14: 21000 | E14: 21000 | F14: 21000
B15: Taxes | C15: 0 | D15: 0 | E15: 0 | F15: 0
B16: Total Disbursements | C16: =SUM(C10:C15) -> 694000 | D16: =SUM(D10:D15) -> 1035000 | E16: =SUM(E10:E15) -> 755000 | F16: =SUM(F10:F15) -> 1081000
B18: Net Cash Flow | C18: =C8-C16 -> 219000 | D18: =D8-D16 -> -92000 | E18: =E8-E16 -> 395000 | F18: =F8-F16 -> -105000
B19: Ending Cash | C19: =C5+C18 -> 3069000 | D19: =D5+D18 -> 2977000 | E19: =E5+E18 -> 3372000 | F19: =F5+F18 -> 3267000

Sheet Live Model
B1: Live 13-Week Rolling Cash Flow Forecast - As Of Week 4 (09/11/2026)
B2: Week # | C2: 5 | D2: 6 | E2: 7 | F2: 8 | G2: 9 | H2: 10 | I2: 11 | J2: 12 | K2: 13 | L2: 14 | M2: 15 | N2: 16 | O2: 17
B3: Week Ending | C3: ='Driver Build'!G4 -> 46283 | D3: ='Driver Build'!H4 -> 46290 | E3: ='Driver Build'!I4 -> 46297 | F3: ='Driver Build'!J4 -> 46304 | G3: ='Driver Build'!K4 -> 46311 | H3: ='Driver Build'!L4 -> 46318 | I3: ='Driver Build'!M4 -> 46325 | J3: ='Driver Build'!N4 -> 46332 | ... O3: ='Driver Build'!S4 -> 46367
B5: Beginning Cash | C5: =Actuals!$F$19 -> 3267000 | D5: =C19 -> 3531721.5 | E5: =D19 -> 3482525.9 | F5: =E19 -> 3513972.5 | G5: =F19 -> 3471299.5 | H5: =G19 -> 3749326.5 | I5: =H19 -> 3628213.1 | J5: =I19 -> 3722143.3 | K5: =J19 -> 3348934.4 | ... O5: =N19 -> 3257387.7
B6: AR Collections | C6: ='Driver Build'!G$6*Assumptions!$C$5+'Driver Build'!F$6*Assumptions!$C$6+'Driver Build'!E$6*Assumptions!$C$7+'Driver Build'!D$6*Assumptions!$C$8+'Driver Build'!C$6*Assumptions!$C$9 -> 1004535.1 | D6: ='Driver Build'!H$6*Assumptions!$C$5+'Driver Build'!G$6*Assumptions!$C$6+'Driver Build'!F$6*Assumptions!$C$7+'Driver Build'!E$6*Assumptions!$C$8+'Driver Build'!D$6*Assumptions!$C$9 -> 1017767.7 | E6: ='Driver Build'!I$6*Assumptions!$C$5+'Driver Build'!H$6*Assumptions!$C$6+'Driver Build'!G$6*Assumptions!$C$7+'Driver Build'!F$6*Assumptions!$C$8+'Driver Build'!E$6*Assumptions!$C$9 -> 1030583.5 | F6: ='Driver Build'!J$6*Assumptions!$C$5+'Driver Build'!I$6*Assumptions!$C$6+'Driver Build'!H$6*Assumptions!$C$7+'Driver Build'!G$6*Assumptions!$C$8+'Driver Build'!F$6*Assumptions!$C$9 -> 1041469 | G6: ='Driver Build'!K$6*Assumptions!$C$5+'Driver Build'!J$6*Assumptions!$C$6+'Driver Build'!I$6*Assumptions!$C$7+'Driver Build'!H$6*Assumptions!$C$8+'Driver Build'!G$6*Assumptions!$C$9 -> 1048734.5 | H6: ='Driver Build'!L$6*Assumptions!$C$5+'Driver Build'!K$6*Assumptions!$C$6+'Driver Build'!J$6*Assumptions!$C$7+'Driver Build'!I$6*Assumptions!$C$8+'Driver Build'!H$6*Assumptions!$C$9 -> 1056137.4 | I6: ='Driver Build'!M$6*Assumptions!$C$5+'Driver Build'!L$6*Assumptions!$C$6+'Driver Build'!K$6*Assumptions!$C$7+'Driver Build'!J$6*Assumptions!$C$8+'Driver Build'!I$6*Assumptions!$C$9 -> 1047299.2 | J6: ='Driver Build'!N$6*Assumptions!$C$5+'Driver Build'!M$6*Assumptions!$C$6+'Driver Build'!L$6*Assumptions!$C$7+'Driver Build'!K$6*Assumptions!$C$8+'Driver Build'!J$6*Assumptions!$C$9 -> 1017108.4 | ... O6: ='Driver Build'!S$6*Assumptions!$C$5+'Driver Build'!R$6*Assumptions!$C$6+'Driver Build'!Q$6*Assumptions!$C$7+'Driver Build'!P$6*Assumptions!$C$8+'Driver Build'!O$6*Assumptions!$C$9 -> 770228.23
B7: Other Receipts | C7: =Assumptions!C46 -> 8000 | D7: =Assumptions!D46 -> 8000 | E7: =Assumptions!E46 -> 8000 | F7: =Assumptions!F46 -> 8000 | G7: =Assumptions!G46 -> 8000 | H7: =Assumptions!H46 -> 8000 | I7: =Assumptions!I46 -> 8000 | J7: =Assumptions!J46 -> 8000 | ... O7: =Assumptions!O46 -> 8000
B8: Total Cash Receipts | C8: =SUM(C6:C7) -> 1012535.1 | D8: =SUM(D6:D7) -> 1025767.7 | E8: =SUM(E6:E7) -> 1038583.5 | F8: =SUM(F6:F7) -> 1049469 | G8: =SUM(G6:G7) -> 1056734.5 | H8: =SUM(H6:H7) -> 1064137.4 | I8: =SUM(I6:I7) -> 1055299.2 | J8: =SUM(J6:J7) -> 1025108.4 | ... O8: =SUM(O6:O7) -> 778228.23
B10: AP Payments | C10: ='Driver Build'!G$7*Assumptions!$C$15+'Driver Build'!F$7*Assumptions!$C$16+'Driver Build'!E$7*Assumptions!$C$17+'Driver Build'!D$7*Assumptions!$C$18+'Driver Build'!C$7*Assumptions!$C$19 -> 631813.61 | D10: ='Driver Build'!H$7*Assumptions!$C$15+'Driver Build'!G$7*Assumptions!$C$16+'Driver Build'!F$7*Assumptions!$C$17+'Driver Build'!E$7*Assumptions!$C$18+'Driver Build'!D$7*Assumptions!$C$19 -> 640963.36 | E10: ='Driver Build'!I$7*Assumptions!$C$15+'Driver Build'!H$7*Assumptions!$C$16+'Driver Build'!G$7*Assumptions!$C$17+'Driver Build'!F$7*Assumptions!$C$18+'Driver Build'!E$7*Assumptions!$C$19 -> 651136.93 | F10: ='Driver Build'!J$7*Assumptions!$C$15+'Driver Build'!I$7*Assumptions!$C$16+'Driver Build'!H$7*Assumptions!$C$17+'Driver Build'!G$7*Assumptions!$C$18+'Driver Build'!F$7*Assumptions!$C$19 -> 658141.95 | G10: ='Driver Build'!K$7*Assumptions!$C$15+'Driver Build'!J$7*Assumptions!$C$16+'Driver Build'!I$7*Assumptions!$C$17+'Driver Build'!H$7*Assumptions!$C$18+'Driver Build'!G$7*Assumptions!$C$19 -> 662707.54 | H10: ='Driver Build'!L$7*Assumptions!$C$15+'Driver Build'!K$7*Assumptions!$C$16+'Driver Build'!J$7*Assumptions!$C$17+'Driver Build'!I$7*Assumptions!$C$18+'Driver Build'!H$7*Assumptions!$C$19 -> 666250.81 | I10: ='Driver Build'!M$7*Assumptions!$C$15+'Driver Build'!L$7*Assumptions!$C$16+'Driver Build'!K$7*Assumptions!$C$17+'Driver Build'!J$7*Assumptions!$C$18+'Driver Build'!I$7*Assumptions!$C$19 -> 665369 | J10: ='Driver Build'!N$7*Assumptions!$C$15+'Driver Build'!M$7*Assumptions!$C$16+'Driver Build'!L$7*Assumptions!$C$17+'Driver Build'!K$7*Assumptions!$C$18+'Driver Build'!J$7*Assumptions!$C$19 -> 654317.32 | ... O10: ='Driver Build'!S$7*Assumptions!$C$15+'Driver Build'!R$7*Assumptions!$C$16+'Driver Build'!Q$7*Assumptions!$C$17+'Driver Build'!P$7*Assumptions!$C$18+'Driver Build'!O$7*Assumptions!$C$19 -> 479012.99
B11: Payroll | C11: =Assumptions!C41 -> 0 | D11: =Assumptions!D41 -> 318000 | E11: =Assumptions!E41 -> 0 | F11: =Assumptions!F41 -> 318000 | G11: =Assumptions!G41 -> 0 | H11: =Assumptions!H41 -> 318000 | I11: =Assumptions!I41 -> 0 | J11: =Assumptions!J41 -> 318000 | ... O11: =Assumptions!O41 -> 0
B12: Opex | C12: =Assumptions!C42 -> 95000 | D12: =Assumptions!D42 -> 95000 | E12: =Assumptions!E42 -> 95000 | F12: =Assumptions!F42 -> 95000 | G12: =Assumptions!G42 -> 95000 | H12: =Assumptions!H42 -> 95000 | I12: =Assumptions!I42 -> 275000 | J12: =Assumptions!J42 -> 95000 | ... O12: =Assumptions!O42 -> 95000
B13: Capex | C13: =Assumptions!C43 -> 0 | D13: =Assumptions!D43 -> 0 | E13: =Assumptions!E43 -> 240000 | F13: =Assumptions!F43 -> 0 | G13: =Assumptions!G43 -> 0 | H13: =Assumptions!H43 -> 85000 | I13: =Assumptions!I43 -> 0 | J13: =Assumptions!J43 -> 0 | ... O13: =Assumptions!O43 -> 0
B14: Debt Service | C14: =Assumptions!C44 -> 21000 | D14: =Assumptions!D44 -> 21000 | E14: =Assumptions!E44 -> 21000 | F14: =Assumptions!F44 -> 21000 | G14: =Assumptions!G44 -> 21000 | H14: =Assumptions!H44 -> 21000 | I14: =Assumptions!I44 -> 21000 | J14: =Assumptions!J44 -> 21000 | ... O14: =Assumptions!O44 -> 21000
B15: Taxes | C15: =Assumptions!C45 -> 0 | D15: =Assumptions!D45 -> 0 | E15: =Assumptions!E45 -> 0 | F15: =Assumptions!F45 -> 0 | G15: =Assumptions!G45 -> 0 | H15: =Assumptions!H45 -> 0 | I15: =Assumptions!I45 -> 0 | J15: =Assumptions!J45 -> 310000 | ... O15: =Assumptions!O45 -> 0
B16: Total Disbursements | C16: =SUM(C10:C15) -> 747813.61 | D16: =SUM(D10:D15) -> 1074963.4 | E16: =SUM(E10:E15) -> 1007136.9 | F16: =SUM(F10:F15) -> 1092141.9 | G16: =SUM(G10:G15) -> 778707.54 | H16: =SUM(H10:H15) -> 1185250.8 | I16: =SUM(I10:I15) -> 961369 | J16: =SUM(J10:J15) -> 1398317.3 | ... O16: =SUM(O10:O15) -> 595012.99
B18: Net Cash Flow | C18: =C8-C16 -> 264721.51 | D18: =D8-D16 -> -49195.641 | E18: =E8-E16 -> 31446.581 | F18: =F8-F16 -> -42672.921 | G18: =G8-G16 -> 278026.95 | H18: =H8-H16 -> -121113.39 | I18: =I8-I16 -> 93930.234 | J18: =J8-J16 -> -373208.93 | ... O18: =O8-O16 -> 183215.24
B19: Ending Cash | C19: =C5+C18 -> 3531721.5 | D19: =D5+D18 -> 3482525.9 | E19: =E5+E18 -> 3513972.5 | F19: =F5+F18 -> 3471299.5 | G19: =G5+G18 -> 3749326.5 | H19: =H5+H18 -> 3628213.1 | I19: =I5+I18 -> 3722143.3 | J19: =J5+J18 -> 3348934.4 | ... O19: =O5+O18 -> 3440602.9
B21: Minimum Cash Covenant | C21: =Assumptions!$C$28 -> 1200000 | D21: =Assumptions!$C$28 -> 1200000 | E21: =Assumptions!$C$28 -> 1200000 | F21: =Assumptions!$C$28 -> 1200000 | G21: =Assumptions!$C$28 -> 1200000 | H21: =Assumptions!$C$28 -> 1200000 | I21: =Assumptions!$C$28 -> 1200000 | J21: =Assumptions!$C$28 -> 1200000 | ... O21: =Assumptions!$C$28 -> 1200000
B22: Covenant Headroom | C22: =C19-C21 -> 2331721.5 | D22: =D19-D21 -> 2282525.9 | E22: =E19-E21 -> 2313972.5 | F22: =F19-F21 -> 2271299.5 | G22: =G19-G21 -> 2549326.5 | H22: =H19-H21 -> 2428213.1 | I22: =I19-I21 -> 2522143.3 | J22: =J19-J21 -> 2148934.4 | ... O22: =O19-O21 -> 2240602.9

Sheet Snapshot Log
A1: Snapshot Log
A2: Append-only forecast history. Each weekly roll appends that week's 13-week forecast (Type = Forecast); each week close appends its Actual (Type = Actual). Existing rows are never overwritten. Variance Calc reads this table with SUMIFS to compare actuals with earlier forecast vintages.
A4: AsOfWeek | B4: ForecastWeek | C4: Category | D4: Amount | E4: Type
A5: 0 | B5: 1 | C5: AR Collections | D5: 931500 | E5: Forecast
A6: 0 | B6: 1 | C6: Other Receipts | D6: 8000 | E6: Forecast
A7: 0 | B7: 1 | C7: AP Payments | D7: 588500 | E7: Forecast
A8: 0 | B8: 1 | C8: Payroll | D8: 0 | E8: Forecast
A9: 0 | B9: 1 | C9: Opex | D9: 95000 | E9: Forecast
A10: 0 | B10: 1 | C10: Capex | D10: 0 | E10: Forecast
A11: 0 | B11: 1 | C11: Debt Service | D11: 21000 | E11: Forecast
A12: 0 | B12: 1 | C12: Taxes | D12: 0 | E12: Forecast
A13: 0 | B13: 2 | C13: AR Collections | D13: 954050 | E13: Forecast
A14: 0 | B14: 2 | C14: Other Receipts | D14: 8000 | E14: Forecast
A15: 0 | B15: 2 | C15: AP Payments | D15: 600078 | E15: Forecast
A16: 0 | B16: 2 | C16: Payroll | D16: 312000 | E16: Forecast
... A556: 4 | B556: 4 | C556: Taxes | D556: 0 | E556: Actual

Sheet Variance Calc
B1: Variance vs. Prior Week's Forecast - Closed Weeks 1- 4
B3: Week 1 (Week Ending 08/21/2026)
B4: Category | C4: Actual | D4: Prior Forecast | E4: Variance $ | F4: Variance %
B5: AR Collections | C5: =SUMIFS('Snapshot Log'!$D:$D,'Snapshot Log'!$B:$B,1,'Snapshot Log'!$C:$C,$B5,'Snapshot Log'!$E:$E,"Actual") -> 905000 | D5: =SUMIFS('Snapshot Log'!$D:$D,'Snapshot Log'!$A:$A,1-1,'Snapshot Log'!$B:$B,1,'Snapshot Log'!$C:$C,$B5,'Snapshot Log'!$E:$E,"Forecast") -> 931500 | E5: =C5-D5 -> -26500 | F5: =IFERROR(E5/D5,"n/a") -> -0.028448739
B6: Other Receipts | C6: =SUMIFS('Snapshot Log'!$D:$D,'Snapshot Log'!$B:$B,1,'Snapshot Log'!$C:$C,$B6,'Snapshot Log'!$E:$E,"Actual") -> 8000 | D6: =SUMIFS('Snapshot Log'!$D:$D,'Snapshot Log'!$A:$A,1-1,'Snapshot Log'!$B:$B,1,'Snapshot Log'!$C:$C,$B6,'Snapshot Log'!$E:$E,"Forecast") -> 8000 | E6: =C6-D6 -> 0 | F6: =IFERROR(E6/D6,"n/a") -> 0
B7: AP Payments | C7: =SUMIFS('Snapshot Log'!$D:$D,'Snapshot Log'!$B:$B,1,'Snapshot Log'!$C:$C,$B7,'Snapshot Log'!$E:$E,"Actual") -> 580000 | D7: =SUMIFS('Snapshot Log'!$D:$D,'Snapshot Log'!$A:$A,1-1,'Snapshot Log'!$B:$B,1,'Snapshot Log'!$C:$C,$B7,'Snapshot Log'!$E:$E,"Forecast") -> 588500 | E7: =C7-D7 -> -8500 | F7: =IFERROR(E7/D7,"n/a") -> -0.0144435
B8: Payroll | C8: =SUMIFS('Snapshot Log'!$D:$D,'Snapshot Log'!$B:$B,1,'Snapshot Log'!$C:$C,$B8,'Snapshot Log'!$E:$E,"Actual") -> 0 | D8: =SUMIFS('Snapshot Log'!$D:$D,'Snapshot Log'!$A:$A,1-1,'Snapshot Log'!$B:$B,1,'Snapshot Log'!$C:$C,$B8,'Snapshot Log'!$E:$E,"Forecast") -> 0 | E8: =C8-D8 -> 0 | F8: =IFERROR(E8/D8,"n/a") -> n/a
B9: Opex | C9: =SUMIFS('Snapshot Log'!$D:$D,'Snapshot Log'!$B:$B,1,'Snapshot Log'!$C:$C,$B9,'Snapshot Log'!$E:$E,"Actual") -> 93000 | D9: =SUMIFS('Snapshot Log'!$D:$D,'Snapshot Log'!$A:$A,1-1,'Snapshot Log'!$B:$B,1,'Snapshot Log'!$C:$C,$B9,'Snapshot Log'!$E:$E,"Forecast") -> 95000 | E9: =C9-D9 -> -2000 | F9: =IFERROR(E9/D9,"n/a") -> -0.021052632
B10: Capex | C10: =SUMIFS('Snapshot Log'!$D:$D,'Snapshot Log'!$B:$B,1,'Snapshot Log'!$C:$C,$B10,'Snapshot Log'!$E:$E,"Actual") -> 0 | D10: =SUMIFS('Snapshot Log'!$D:$D,'Snapshot Log'!$A:$A,1-1,'Snapshot Log'!$B:$B,1,'Snapshot Log'!$C:$C,$B10,'Snapshot Log'!$E:$E,"Forecast") -> 0 | E10: =C10-D10 -> 0 | F10: =IFERROR(E10/D10,"n/a") -> n/a
B11: Debt Service | C11: =SUMIFS('Snapshot Log'!$D:$D,'Snapshot Log'!$B:$B,1,'Snapshot Log'!$C:$C,$B11,'Snapshot Log'!$E:$E,"Actual") -> 21000 | D11: =SUMIFS('Snapshot Log'!$D:$D,'Snapshot Log'!$A:$A,1-1,'Snapshot Log'!$B:$B,1,'Snapshot Log'!$C:$C,$B11,'Snapshot Log'!$E:$E,"Forecast") -> 21000 | E11: =C11-D11 -> 0 | F11: =IFERROR(E11/D11,"n/a") -> 0
B12: Taxes | C12: =SUMIFS('Snapshot Log'!$D:$D,'Snapshot Log'!$B:$B,1,'Snapshot Log'!$C:$C,$B12,'Snapshot Log'!$E:$E,"Actual") -> 0 | D12: =SUMIFS('Snapshot Log'!$D:$D,'Snapshot Log'!$A:$A,1-1,'Snapshot Log'!$B:$B,1,'Snapshot Log'!$C:$C,$B12,'Snapshot Log'!$E:$E,"Forecast") -> 0 | E12: =C12-D12 -> 0 | F12: =IFERROR(E12/D12,"n/a") -> n/a
B13: Total | C13: =SUM(C5:C12) -> 1607000 | D13: =SUM(D5:D12) -> 1644000 | E13: =SUM(E5:E12) -> -37000 | F13: =IFERROR(E13/D13,"n/a") -> -0.022506083
B15: Week 2 (Week Ending 08/28/2026)
B16: Category | C16: Actual | D16: Prior Forecast | E16: Variance $ | F16: Variance %
B17: AR Collections | C17: =SUMIFS('Snapshot Log'!$D:$D,'Snapshot Log'!$B:$B,2,'Snapshot Log'!$C:$C,$B17,'Snapshot Log'!$E:$E,"Actual") -> 935000 | D17: =SUMIFS('Snapshot Log'!$D:$D,'Snapshot Log'!$A:$A,2-1,'Snapshot Log'!$B:$B,2,'Snapshot Log'!$C:$C,$B17,'Snapshot Log'!$E:$E,"Forecast") -> 948500 | E17: =C17-D17 -> -13500 | F17: =IFERROR(E17/D17,"n/a") -> -0.014232999
B18: Other Receipts | C18: =SUMIFS('Snapshot Log'!$D:$D,'Snapshot Log'!$B:$B,2,'Snapshot Log'!$C:$C,$B18,'Snapshot Log'!$E:$E,"Actual") -> 8000 | D18: =SUMIFS('Snapshot Log'!$D:$D,'Snapshot Log'!$A:$A,2-1,'Snapshot Log'!$B:$B,2,'Snapshot Log'!$C:$C,$B18,'Snapshot Log'!$E:$E,"Forecast") -> 8000 | E18: =C18-D18 -> 0 | F18: =IFERROR(E18/D18,"n/a") -> 0
B19: AP Payments | C19: =SUMIFS('Snapshot Log'!$D:$D,'Snapshot Log'!$B:$B,2,'Snapshot Log'!$C:$C,$B19,'Snapshot Log'!$E:$E,"Actual") -> 605000 | D19: =SUMIFS('Snapshot Log'!$D:$D,'Snapshot Log'!$A:$A,2-1,'Snapshot Log'!$B:$B,2,'Snapshot Log'!$C:$C,$B19,'Snapshot Log'!$E:$E,"Forecast") -> 598078 | E19: =C19-D19 -> 6922 | F19: =IFERROR(E19/D19,"n/a") -> 0.011573741
B20: Payroll | C20: =SUMIFS('Snapshot Log'!$D:$D,'Snapshot Log'!$B:$B,2,'Snapshot Log'!$C:$C,$B20,'Snapshot Log'!$E:$E,"Actual") -> 315000 | D20: =SUMIFS('Snapshot Log'!$D:$D,'Snapshot Log'!$A:$A,2-1,'Snapshot Log'!$B:$B,2,'Snapshot Log'!$C:$C,$B20,'Snapshot Log'!$E:$E,"Forecast") -> 312000 | E20: =C20-D20 -> 3000 | F20: =IFERROR(E20/D20,"n/a") -> 0.0096153846
B21: Opex | C21: =SUMIFS('Snapshot Log'!$D:$D,'Snapshot Log'!$B:$B,2,'Snapshot Log'!$C:$C,$B21,'Snapshot Log'!$E:$E,"Actual") -> 94000 | D21: =SUMIFS('Snapshot Log'!$D:$D,'Snapshot Log'!$A:$A,2-1,'Snapshot Log'!$B:$B,2,'Snapshot Log'!$C:$C,$B21,'Snapshot Log'!$E:$E,"Forecast") -> 95000 | E21: =C21-D21 -> -1000 | F21: =IFERROR(E21/D21,"n/a") -> -0.010526316
B22: Capex | C22: =SUMIFS('Snapshot Log'!$D:$D,'Snapshot Log'!$B:$B,2,'Snapshot Log'!$C:$C,$B22,'Snapshot Log'!$E:$E,"Actual") -> 0 | D22: =SUMIFS('Snapshot Log'!$D:$D,'Snapshot Log'!$A:$A,2-1,'Snapshot Log'!$B:$B,2,'Snapshot Log'!$C:$C,$B22,'Snapshot Log'!$E:$E,"Forecast") -> 0 | E22: =C22-D22 -> 0 | F22: =IFERROR(E22/D22,"n/a") -> n/a
B23: Debt Service | C23: =SUMIFS('Snapshot Log'!$D:$D,'Snapshot Log'!$B:$B,2,'Snapshot Log'!$C:$C,$B23,'Snapshot Log'!$E:$E,"Actual") -> 21000 | D23: =SUMIFS('Snapshot Log'!$D:$D,'Snapshot Log'!$A:$A,2-1,'Snapshot Log'!$B:$B,2,'Snapshot Log'!$C:$C,$B23,'Snapshot Log'!$E:$E,"Forecast") -> 21000 | E23: =C23-D23 -> 0 | F23: =IFERROR(E23/D23,"n/a") -> 0
B24: Taxes | C24: =SUMIFS('Snapshot Log'!$D:$D,'Snapshot Log'!$B:$B,2,'Snapshot Log'!$C:$C,$B24,'Snapshot Log'!$E:$E,"Actual") -> 0 | D24: =SUMIFS('Snapshot Log'!$D:$D,'Snapshot Log'!$A:$A,2-1,'Snapshot Log'!$B:$B,2,'Snapshot Log'!$C:$C,$B24,'Snapshot Log'!$E:$E,"Forecast") -> 0 | E24: =C24-D24 -> 0 | F24: =IFERROR(E24/D24,"n/a") -> n/a
B25: Total | C25: =SUM(C17:C24) -> 1978000 | D25: =SUM(D17:D24) -> 1982578 | E25: =SUM(E17:E24) -> -4578 | F25: =IFERROR(E25/D25,"n/a") -> -0.0023091147
B27: Week 3 (Week Ending 09/04/2026)
B28: Category | C28: Actual | D28: Prior Forecast | E28: Variance $ | F28: Variance %
B29: AR Collections | C29: =SUMIFS('Snapshot Log'!$D:$D,'Snapshot Log'!$B:$B,3,'Snapshot Log'!$C:$C,$B29,'Snapshot Log'!$E:$E,"Actual") -> 1142000 | D29: =SUMIFS('Snapshot Log'!$D:$D,'Snapshot Log'!$A:$A,3-1,'Snapshot Log'!$B:$B,3,'Snapshot Log'!$C:$C,$B29,'Snapshot Log'!$E:$E,"Forecast") -> 970309 | E29: =C29-D29 -> 171691 | F29: =IFERROR(E29/D29,"n/a") -> 0.17694466
B30: Other Receipts | C30: =SUMIFS('Snapshot Log'!$D:$D,'Snapshot Log'!$B:$B,3,'Snapshot Log'!$C:$C,$B30,'Snapshot Log'!$E:$E,"Actual") -> 8000 | D30: =SUMIFS('Snapshot Log'!$D:$D,'Snapshot Log'!$A:$A,3-1,'Snapshot Log'!$B:$B,3,'Snapshot Log'!$C:$C,$B30,'Snapshot Log'!$E:$E,"Forecast") -> 8000 | E30: =C30-D30 -> 0 | F30: =IFERROR(E30/D30,"n/a") -> 0
B31: AP Payments | C31: =SUMIFS('Snapshot Log'!$D:$D,'Snapshot Log'!$B:$B,3,'Snapshot Log'!$C:$C,$B31,'Snapshot Log'!$E:$E,"Actual") -> 598000 | D31: =SUMIFS('Snapshot Log'!$D:$D,'Snapshot Log'!$A:$A,3-1,'Snapshot Log'!$B:$B,3,'Snapshot Log'!$C:$C,$B31,'Snapshot Log'!$E:$E,"Forecast") -> 612278 | E31: =C31-D31 -> -14278 | F31: =IFERROR(E31/D31,"n/a") -> -0.023319473
B32: Payroll | C32: =SUMIFS('Snapshot Log'!$D:$D,'Snapshot Log'!$B:$B,3,'Snapshot Log'!$C:$C,$B32,'Snapshot Log'!$E:$E,"Actual") -> 0 | D32: =SUMIFS('Snapshot Log'!$D:$D,'Snapshot Log'!$A:$A,3-1,'Snapshot Log'!$B:$B,3,'Snapshot Log'!$C:$C,$B32,'Snapshot Log'!$E:$E,"Forecast") -> 0 | E32: =C32-D32 -> 0 | F32: =IFERROR(E32/D32,"n/a") -> n/a
B33: Opex | C33: =SUMIFS('Snapshot Log'!$D:$D,'Snapshot Log'!$B:$B,3,'Snapshot Log'!$C:$C,$B33,'Snapshot Log'!$E:$E,"Actual") -> 91000 | D33: =SUMIFS('Snapshot Log'!$D:$D,'Snapshot Log'!$A:$A,3-1,'Snapshot Log'!$B:$B,3,'Snapshot Log'!$C:$C,$B33,'Snapshot Log'!$E:$E,"Forecast") -> 95000 | E33: =C33-D33 -> -4000 | F33: =IFERROR(E33/D33,"n/a") -> -0.042105263
B34: Capex | C34: =SUMIFS('Snapshot Log'!$D:$D,'Snapshot Log'!$B:$B,3,'Snapshot Log'!$C:$C,$B34,'Snapshot Log'!$E:$E,"Actual") -> 45000 | D34: =SUMIFS('Snapshot Log'!$D:$D,'Snapshot Log'!$A:$A,3-1,'Snapshot Log'!$B:$B,3,'Snapshot Log'!$C:$C,$B34,'Snapshot Log'!$E:$E,"Forecast") -> 0 | E34: =C34-D34 -> 45000 | F34: =IFERROR(E34/D34,"n/a") -> n/a
B35: Debt Service | C35: =SUMIFS('Snapshot Log'!$D:$D,'Snapshot Log'!$B:$B,3,'Snapshot Log'!$C:$C,$B35,'Snapshot Log'!$E:$E,"Actual") -> 21000 | D35: =SUMIFS('Snapshot Log'!$D:$D,'Snapshot Log'!$A:$A,3-1,'Snapshot Log'!$B:$B,3,'Snapshot Log'!$C:$C,$B35,'Snapshot Log'!$E:$E,"Forecast") -> 21000 | E35: =C35-D35 -> 0 | F35: =IFERROR(E35/D35,"n/a") -> 0
B36: Taxes | C36: =SUMIFS('Snapshot Log'!$D:$D,'Snapshot Log'!$B:$B,3,'Snapshot Log'!$C:$C,$B36,'Snapshot Log'!$E:$E,"Actual") -> 0 | D36: =SUMIFS('Snapshot Log'!$D:$D,'Snapshot Log'!$A:$A,3-1,'Snapshot Log'!$B:$B,3,'Snapshot Log'!$C:$C,$B36,'Snapshot Log'!$E:$E,"Forecast") -> 0 | E36: =C36-D36 -> 0 | F36: =IFERROR(E36/D36,"n/a") -> n/a
B37: Total | C37: =SUM(C29:C36) -> 1905000 | D37: =SUM(D29:D36) -> 1706587 | E37: =SUM(E29:E36) -> 198413 | F37: =IFERROR(E37/D37,"n/a") -> 0.11626304
B39: Week 4 (Week Ending 09/11/2026)
B40: Category | C40: Actual | D40: Prior Forecast | E40: Variance $ | F40: Variance %
B41: AR Collections | C41: =SUMIFS('Snapshot Log'!$D:$D,'Snapshot Log'!$B:$B,4,'Snapshot Log'!$C:$C,$B41,'Snapshot Log'!$E:$E,"Actual") -> 968000 | D41: =SUMIFS('Snapshot Log'!$D:$D,'Snapshot Log'!$A:$A,4-1,'Snapshot Log'!$B:$B,4,'Snapshot Log'!$C:$C,$B41,'Snapshot Log'!$E:$E,"Forecast") -> 995914 | E41: =C41-D41 -> -27914 | F41: =IFERROR(E41/D41,"n/a") -> -0.028028525
B42: Other Receipts | C42: =SUMIFS('Snapshot Log'!$D:$D,'Snapshot Log'!$B:$B,4,'Snapshot Log'!$C:$C,$B42,'Snapshot Log'!$E:$E,"Actual") -> 8000 | D42: =SUMIFS('Snapshot Log'!$D:$D,'Snapshot Log'!$A:$A,4-1,'Snapshot Log'!$B:$B,4,'Snapshot Log'!$C:$C,$B42,'Snapshot Log'!$E:$E,"Forecast") -> 8000 | E42: =C42-D42 -> 0 | F42: =IFERROR(E42/D42,"n/a") -> 0
B43: AP Payments | C43: =SUMIFS('Snapshot Log'!$D:$D,'Snapshot Log'!$B:$B,4,'Snapshot Log'!$C:$C,$B43,'Snapshot Log'!$E:$E,"Actual") -> 642000 | D43: =SUMIFS('Snapshot Log'!$D:$D,'Snapshot Log'!$A:$A,4-1,'Snapshot Log'!$B:$B,4,'Snapshot Log'!$C:$C,$B43,'Snapshot Log'!$E:$E,"Forecast") -> 621858 | E43: =C43-D43 -> 20142 | F43: =IFERROR(E43/D43,"n/a") -> 0.032390031
B44: Payroll | C44: =SUMIFS('Snapshot Log'!$D:$D,'Snapshot Log'!$B:$B,4,'Snapshot Log'!$C:$C,$B44,'Snapshot Log'!$E:$E,"Actual") -> 322000 | D44: =SUMIFS('Snapshot Log'!$D:$D,'Snapshot Log'!$A:$A,4-1,'Snapshot Log'!$B:$B,4,'Snapshot Log'!$C:$C,$B44,'Snapshot Log'!$E:$E,"Forecast") -> 312000 | E44: =C44-D44 -> 10000 | F44: =IFERROR(E44/D44,"n/a") -> 0.032051282
...

Sheet Scenario
B1: Scenario Comparison - Best / Base / Worst Case (13-Week Horizon)
B3: Scenario Levers
B4: Scenario | C4: Receipts Adj. | D4: Disbursements Adj.
B5: Best | C5: 0.05 | D5: -0.03
B6: Base | C6: 0 | D6: 0
B7: Worst | C7: -0.08 | D7: 0.04
B9: Best Case
B10: Week # | C10: 5 | D10: 6 | E10: 7 | F10: 8 | G10: 9 | H10: 10 | I10: 11 | J10: 12 | K10: 13 | L10: 14 | M10: 15 | N10: 16 | O10: 17
B11: Total Receipts | C11: ='Live Model'!C8*(1+$C$5) -> 1063161.9 | D11: ='Live Model'!D8*(1+$C$5) -> 1077056.1 | E11: ='Live Model'!E8*(1+$C$5) -> 1090512.7 | F11: ='Live Model'!F8*(1+$C$5) -> 1101942.5 | G11: ='Live Model'!G8*(1+$C$5) -> 1109571.2 | H11: ='Live Model'!H8*(1+$C$5) -> 1117344.3 | I11: ='Live Model'!I8*(1+$C$5) -> 1108064.2 | J11: ='Live Model'!J8*(1+$C$5) -> 1076363.8 | ... O11: ='Live Model'!O8*(1+$C$5) -> 817139.64
B12: Total Disbursements | C12: ='Live Model'!C16*(1+$D$5) -> 725379.2 | D12: ='Live Model'!D16*(1+$D$5) -> 1042714.5 | E12: ='Live Model'!E16*(1+$D$5) -> 976922.82 | F12: ='Live Model'!F16*(1+$D$5) -> 1059377.7 | G12: ='Live Model'!G16*(1+$D$5) -> 755346.31 | H12: ='Live Model'!H16*(1+$D$5) -> 1149693.3 | I12: ='Live Model'!I16*(1+$D$5) -> 932527.93 | J12: ='Live Model'!J16*(1+$D$5) -> 1356367.8 | ... O12: ='Live Model'!O16*(1+$D$5) -> 577162.6
B13: Net Cash Flow | C13: =C11-C12 -> 337782.68 | D13: =D11-D12 -> 34341.645 | E13: =E11-E12 -> 113589.86 | F13: =F11-F12 -> 42564.788 | G13: =G11-G12 -> 354224.9 | H13: =H11-H12 -> -32348.995 | I13: =I11-I12 -> 175536.26 | J13: =J11-J12 -> -280003.99 | ... O13: =O11-O12 -> 239977.04
B14: Beginning Cash | C14: ='Live Model'!C5 -> 3267000 | D14: =C15 -> 3604782.7 | E14: =D15 -> 3639124.3 | F14: =E15 -> 3752714.2 | G14: =F15 -> 3795279 | H14: =G15 -> 4149503.9 | I14: =H15 -> 4117154.9 | J14: =I15 -> 4292691.1 | K14: =J15 -> 4012687.2 | ... O14: =N15 -> 4208243.7
B15: Ending Cash | C15: =C14+C13 -> 3604782.7 | D15: =D14+D13 -> 3639124.3 | E15: =E14+E13 -> 3752714.2 | F15: =F14+F13 -> 3795279 | G15: =G14+G13 -> 4149503.9 | H15: =H14+H13 -> 4117154.9 | I15: =I14+I13 -> 4292691.1 | J15: =J14+J13 -> 4012687.2 | ... O15: =O14+O13 -> 4448220.7
B16: Covenant Headroom | C16: =C15-'Live Model'!C21 -> 2404782.7 | D16: =D15-'Live Model'!D21 -> 2439124.3 | E16: =E15-'Live Model'!E21 -> 2552714.2 | F16: =F15-'Live Model'!F21 -> 2595279 | G16: =G15-'Live Model'!G21 -> 2949503.9 | H16: =H15-'Live Model'!H21 -> 2917154.9 | I16: =I15-'Live Model'!I21 -> 3092691.1 | J16: =J15-'Live Model'!J21 -> 2812687.2 | ... O16: =O15-'Live Model'!O21 -> 3248220.7
B18: Base Case
B19: Week # | C19: 5 | D19: 6 | E19: 7 | F19: 8 | G19: 9 | H19: 10 | I19: 11 | J19: 12 | K19: 13 | L19: 14 | M19: 15 | N19: 16 | O19: 17
B20: Total Receipts | C20: ='Live Model'!C8*(1+$C$6) -> 1012535.1 | D20: ='Live Model'!D8*(1+$C$6) -> 1025767.7 | E20: ='Live Model'!E8*(1+$C$6) -> 1038583.5 | F20: ='Live Model'!F8*(1+$C$6) -> 1049469 | G20: ='Live Model'!G8*(1+$C$6) -> 1056734.5 | H20: ='Live Model'!H8*(1+$C$6) -> 1064137.4 | I20: ='Live Model'!I8*(1+$C$6) -> 1055299.2 | J20: ='Live Model'!J8*(1+$C$6) -> 1025108.4 | ... O20: ='Live Model'!O8*(1+$C$6) -> 778228.23
B21: Total Disbursements | C21: ='Live Model'!C16*(1+$D$6) -> 747813.61 | D21: ='Live Model'!D16*(1+$D$6) -> 1074963.4 | E21: ='Live Model'!E16*(1+$D$6) -> 1007136.9 | F21: ='Live Model'!F16*(1+$D$6) -> 1092141.9 | G21: ='Live Model'!G16*(1+$D$6) -> 778707.54 | H21: ='Live Model'!H16*(1+$D$6) -> 1185250.8 | I21: ='Live Model'!I16*(1+$D$6) -> 961369 | J21: ='Live Model'!J16*(1+$D$6) -> 1398317.3 | ... O21: ='Live Model'!O16*(1+$D$6) -> 595012.99
B22: Net Cash Flow | C22: =C20-C21 -> 264721.51 | D22: =D20-D21 -> -49195.641 | E22: =E20-E21 -> 31446.581 | F22: =F20-F21 -> -42672.921 | G22: =G20-G21 -> 278026.95 | H22: =H20-H21 -> -121113.39 | I22: =I20-I21 -> 93930.234 | J22: =J20-J21 -> -373208.93 | ... O22: =O20-O21 -> 183215.24
B23: Beginning Cash | C23: ='Live Model'!C5 -> 3267000 | D23: =C24 -> 3531721.5 | E23: =D24 -> 3482525.9 | F23: =E24 -> 3513972.5 | G23: =F24 -> 3471299.5 | H23: =G24 -> 3749326.5 | I23: =H24 -> 3628213.1 | J23: =I24 -> 3722143.3 | K23: =J24 -> 3348934.4 | ... O23: =N24 -> 3257387.7
B24: Ending Cash | C24: =C23+C22 -> 3531721.5 | D24: =D23+D22 -> 3482525.9 | E24: =E23+E22 -> 3513972.5 | F24: =F23+F22 -> 3471299.5 | G24: =G23+G22 -> 3749326.5 | H24: =H23+H22 -> 3628213.1 | I24: =I23+I22 -> 3722143.3 | J24: =J23+J22 -> 3348934.4 | ... O24: =O23+O22 -> 3440602.9
B25: Covenant Headroom | C25: =C24-'Live Model'!C21 -> 2331721.5 | D25: =D24-'Live Model'!D21 -> 2282525.9 | E25: =E24-'Live Model'!E21 -> 2313972.5 | F25: =F24-'Live Model'!F21 -> 2271299.5 | G25: =G24-'Live Model'!G21 -> 2549326.5 | H25: =H24-'Live Model'!H21 -> 2428213.1 | I25: =I24-'Live Model'!I21 -> 2522143.3 | J25: =J24-'Live Model'!J21 -> 2148934.4 | ... O25: =O24-'Live Model'!O21 -> 2240602.9
B27: Worst Case
B28: Week # | C28: 5 | D28: 6 | E28: 7 | F28: 8 | G28: 9 | H28: 10 | I28: 11 | J28: 12 | K28: 13 | L28: 14 | M28: 15 | N28: 16 | O28: 17
B29: Total Receipts | C29: ='Live Model'!C8*(1+$C$7) -> 931532.32 | D29: ='Live Model'!D8*(1+$C$7) -> 943706.3 | E29: ='Live Model'!E8*(1+$C$7) -> 955496.83 | F29: ='Live Model'!F8*(1+$C$7) -> 965511.5 | G29: ='Live Model'!G8*(1+$C$7) -> 972195.73 | H29: ='Live Model'!H8*(1+$C$7) -> 979006.43 | I29: ='Live Model'!I8*(1+$C$7) -> 970875.29 | J29: ='Live Model'!J8*(1+$C$7) -> 943099.73 | ... O29: ='Live Model'!O8*(1+$C$7) -> 715969.97
B30: Total Disbursements | C30: ='Live Model'!C16*(1+$D$7) -> 777726.16 | D30: ='Live Model'!D16*(1+$D$7) -> 1117961.9 | E30: ='Live Model'!E16*(1+$D$7) -> 1047422.4 | F30: ='Live Model'!F16*(1+$D$7) -> 1135827.6 | G30: ='Live Model'!G16*(1+$D$7) -> 809855.84 | H30: ='Live Model'!H16*(1+$D$7) -> 1232660.8 | I30: ='Live Model'!I16*(1+$D$7) -> 999823.76 | J30: ='Live Model'!J16*(1+$D$7) -> 1454250 | ... O30: ='Live Model'!O16*(1+$D$7) -> 618813.51
B31: Net Cash Flow | C31: =C29-C30 -> 153806.16 | D31: =D29-D30 -> -174255.59 | E31: =E29-E30 -> -91925.577 | F31: =F29-F30 -> -170316.12 | G31: =G29-G30 -> 162339.89 | H31: =H29-H30 -> -253654.42 | I31: =I29-I30 -> -28948.465 | J31: =J29-J30 -> -511150.29 | ... O31: =O29-O30 -> 97156.462
B32: Beginning Cash | C32: ='Live Model'!C5 -> 3267000 | D32: =C33 -> 3420806.2 | E32: =D33 -> 3246550.6 | F32: =E33 -> 3154625 | G32: =F33 -> 2984308.9 | H32: =G33 -> 3146648.8 | I32: =H33 -> 2892994.3 | J32: =I33 -> 2864045.9 | K32: =J33 -> 2352895.6 | ... O32: =N33 -> 1831151.7
B33: Ending Cash | C33: =C32+C31 -> 3420806.2 | D33: =D32+D31 -> 3246550.6 | E33: =E32+E31 -> 3154625 | F33: =F32+F31 -> 2984308.9 | G33: =G32+G31 -> 3146648.8 | H33: =H32+H31 -> 2892994.3 | I33: =I32+I31 -> 2864045.9 | J33: =J32+J31 -> 2352895.6 | ... O33: =O32+O31 -> 1928308.1
B34: Covenant Headroom | C34: =C33-'Live Model'!C21 -> 2220806.2 | D34: =D33-'Live Model'!D21 -> 2046550.6 | E34: =E33-'Live Model'!E21 -> 1954625 | F34: =F33-'Live Model'!F21 -> 1784308.9 | G34: =G33-'Live Model'!G21 -> 1946648.8 | H34: =H33-'Live Model'!H21 -> 1692994.3 | I34: =I33-'Live Model'!I21 -> 1664045.9 | J34: =J33-'Live Model'!J21 -> 1152895.6 | ... O34: =O33-'Live Model'!O21 -> 728308.13
B36: Summary
B37: Scenario | C37: Week 17 Ending Cash | D37: Min. Covenant Headroom | E37: Avg Weekly Net CF | F37: Weeks of Runway
B38: Best | C38: =O15 -> 4448220.7 | D38: =MIN(C16:O16) -> 2404782.7 | E38: =AVERAGE(C13:O13) -> 90863.134 | F38: =IF(E38>=0,"N/A (cash flow positive)",Actuals!$F$19/-E38) -> N/A (cash flow positive)
B39: Base | C39: =O24 -> 3440602.9 | D39: =MIN(C25:O25) -> 2057387.7 | E39: =AVERAGE(C22:O22) -> 13354.069 | F39: =IF(E39>=0,"N/A (cash flow positive)",Actuals!$F$19/-E39) -> N/A (cash flow positive)
B40: Worst | C40: =O33 -> 1928308.1 | D40: =MIN(C34:O34) -> 631151.67 | E40: =AVERAGE(C31:O31) -> -102976.3 | F40: =IF(E40>=0,"N/A (cash flow positive)",Actuals!$F$19/-E40) -> 31.725747

Sheet KPI Summary
B1: ="KPI Summary - As Of Week "&Assumptions!$C$30&" ("&TEXT(INDEX(Actuals!$C$3:$F$3,Assumptions!$C$30),"mm/dd/yyyy")&")" -> KPI Summary - As Of Week 4 (09/11/2026)
B3: Cash Position
B4: Current Cash (Week 4 actual ending) | C4: =Actuals!$F$19 -> 3267000
B5: 13-Week-Forward Ending Cash (Week 17 forecast) | C5: ='Live Model'!$O$19 -> 3440602.9
B6: Minimum Cash Covenant | C6: =Assumptions!$C$28 -> 1200000
B7: Minimum Covenant Headroom Over Horizon | C7: =MIN('Live Model'!$C$22:$O$22) -> 2057387.7
B8: Average Weekly Net Cash Flow (Base, 13-wk horizon) | C8: =AVERAGE('Live Model'!$C$18:$O$18) -> 13354.069
B9: Weeks of Runway (Base) | C9: =IF(C8>=0,"N/A (cash flow positive)",C4/-C8) -> N/A (cash flow positive)
B11: Latest Close - Variance vs. Prior Week's Forecast (Week 4)
B12: Actual Total Net Cash Flow | C12: =Actuals!$F$18 -> -105000
B13: Forecast Accuracy, 1-Week-Out (Total Receipts, latest closed week) | C13: ='Variance Calc'!$F$66 -> 0.027805171
B14: Forecast Accuracy Trend (Total Cash Receipts, by horizon)
B15: 1-Week-Out Avg (Variance %) | C15: ='Variance Calc'!$D$53 -> 0.061405835
B16: 2-Week-Out Avg (Variance %) | C16: ='Variance Calc'!$D$54 -> 0.073089031
B17: 3-Week-Out Avg (Variance %) | C17: ='Variance Calc'!$D$55 -> 0.096171959
B18: 4-Week-Out Avg (Variance %) | C18: ='Variance Calc'!$D$56 -> 0.021066135
B20: Scenario Comparison - 13 Week Horizon
B21: Scenario | C21: Week 17 Ending Cash | D21: Min. Covenant Headroom | E21: Weeks of Runway
B22: Best | C22: =Scenario!$C$38 -> 4448220.7 | D22: =Scenario!$D$38 -> 2404782.7 | E22: =Scenario!$F$38 -> N/A (cash flow positive)
B23: Base | C23: =Scenario!$C$39 -> 3440602.9 | D23: =Scenario!$D$39 -> 2057387.7 | E23: =Scenario!$F$39 -> N/A (cash flow positive)
B24: Worst | C24: =Scenario!$C$40 -> 1928308.1 | D24: =Scenario!$D$40 -> 631151.67 | E24: =Scenario!$F$40 -> 31.725747

Sheet Chart Data
A1: Chart Data - helper ranges for the Dashboard
A3: Week | B3: Week Ending | C3: Status | D3: Ending Cash | E3: Min Covenant | F3: Receipts | G3: Disbursements | H3: Net Cash Flow
A4: W1 | B4: ='Driver Build'!C4 -> 46255 | C4: ='Driver Build'!C5 -> Actual | D4: =Actuals!C19 -> 3069000 | E4: =Assumptions!$C$28 -> 1200000 | F4: =Actuals!C8 -> 913000 | G4: =Actuals!C16 -> 694000 | H4: =Actuals!C18 -> 219000
A5: W2 | B5: ='Driver Build'!D4 -> 46262 | C5: ='Driver Build'!D5 -> Actual | D5: =Actuals!D19 -> 2977000 | E5: =Assumptions!$C$28 -> 1200000 | F5: =Actuals!D8 -> 943000 | G5: =Actuals!D16 -> 1035000 | H5: =Actuals!D18 -> -92000
A6: W3 | B6: ='Driver Build'!E4 -> 46269 | C6: ='Driver Build'!E5 -> Actual | D6: =Actuals!E19 -> 3372000 | E6: =Assumptions!$C$28 -> 1200000 | F6: =Actuals!E8 -> 1150000 | G6: =Actuals!E16 -> 755000 | H6: =Actuals!E18 -> 395000
A7: W4 | B7: ='Driver Build'!F4 -> 46276 | C7: ='Driver Build'!F5 -> Actual | D7: =Actuals!F19 -> 3267000 | E7: =Assumptions!$C$28 -> 1200000 | F7: =Actuals!F8 -> 976000 | G7: =Actuals!F16 -> 1081000 | H7: =Actuals!F18 -> -105000
A8: W5 | B8: ='Driver Build'!G4 -> 46283 | C8: ='Driver Build'!G5 -> Forecast | D8: ='Live Model'!C19 -> 3531721.5 | E8: =Assumptions!$C$28 -> 1200000 | F8: ='Live Model'!C8 -> 1012535.1 | G8: ='Live Model'!C16 -> 747813.61 | H8: ='Live Model'!C18 -> 264721.51
A9: W6 | B9: ='Driver Build'!H4 -> 46290 | C9: ='Driver Build'!H5 -> Forecast | D9: ='Live Model'!D19 -> 3482525.9 | E9: =Assumptions!$C$28 -> 1200000 | F9: ='Live Model'!D8 -> 1025767.7 | G9: ='Live Model'!D16 -> 1074963.4 | H9: ='Live Model'!D18 -> -49195.641
A10: W7 | B10: ='Driver Build'!I4 -> 46297 | C10: ='Driver Build'!I5 -> Forecast | D10: ='Live Model'!E19 -> 3513972.5 | E10: =Assumptions!$C$28 -> 1200000 | F10: ='Live Model'!E8 -> 1038583.5 | G10: ='Live Model'!E16 -> 1007136.9 | H10: ='Live Model'!E18 -> 31446.581
A11: W8 | B11: ='Driver Build'!J4 -> 46304 | C11: ='Driver Build'!J5 -> Forecast | D11: ='Live Model'!F19 -> 3471299.5 | E11: =Assumptions!$C$28 -> 1200000 | F11: ='Live Model'!F8 -> 1049469 | G11: ='Live Model'!F16 -> 1092141.9 | H11: ='Live Model'!F18 -> -42672.921
A12: W9 | B12: ='Driver Build'!K4 -> 46311 | C12: ='Driver Build'!K5 -> Forecast | D12: ='Live Model'!G19 -> 3749326.5 | E12: =Assumptions!$C$28 -> 1200000 | F12: ='Live Model'!G8 -> 1056734.5 | G12: ='Live Model'!G16 -> 778707.54 | H12: ='Live Model'!G18 -> 278026.95
A13: W10 | B13: ='Driver Build'!L4 -> 46318 | C13: ='Driver Build'!L5 -> Forecast | D13: ='Live Model'!H19 -> 3628213.1 | E13: =Assumptions!$C$28 -> 1200000 | F13: ='Live Model'!H8 -> 1064137.4 | G13: ='Live Model'!H16 -> 1185250.8 | H13: ='Live Model'!H18 -> -121113.39
A14: W11 | B14: ='Driver Build'!M4 -> 46325 | C14: ='Driver Build'!M5 -> Forecast | D14: ='Live Model'!I19 -> 3722143.3 | E14: =Assumptions!$C$28 -> 1200000 | F14: ='Live Model'!I8 -> 1055299.2 | G14: ='Live Model'!I16 -> 961369 | H14: ='Live Model'!I18 -> 93930.234
A15: W12 | B15: ='Driver Build'!N4 -> 46332 | C15: ='Driver Build'!N5 -> Forecast | D15: ='Live Model'!J19 -> 3348934.4 | E15: =Assumptions!$C$28 -> 1200000 | F15: ='Live Model'!J8 -> 1025108.4 | G15: ='Live Model'!J16 -> 1398317.3 | H15: ='Live Model'!J18 -> -373208.93
A16: W13 | B16: ='Driver Build'!O4 -> 46339 | C16: ='Driver Build'!O5 -> Forecast | D16: ='Live Model'!K19 -> 3586448 | E16: =Assumptions!$C$28 -> 1200000 | F16: ='Live Model'!K8 -> 983705.97 | G16: ='Live Model'!K16 -> 746192.35 | H16: ='Live Model'!K18 -> 237513.62
A17: W14 | B17: ='Driver Build'!P4 -> 46346 | C17: ='Driver Build'!P5 -> Forecast | D17: ='Live Model'!L19 -> 3337296.3 | E17: =Assumptions!$C$28 -> 1200000 | F17: ='Live Model'!L8 -> 933169.11 | G17: ='Live Model'!L16 -> 1182320.9 | H17: ='Live Model'!L18 -> -249151.75
A18: W15 | B18: ='Driver Build'!Q4 -> 46353 | C18: ='Driver Build'!Q5 -> Forecast | D18: ='Live Model'!M19 -> 3523967.7 | E18: =Assumptions!$C$28 -> 1200000 | F18: ='Live Model'!M8 -> 861909.32 | G18: ='Live Model'!M16 -> 675237.84 | H18: ='Live Model'!M18 -> 186671.48
A19: W16 | B19: ='Driver Build'!R4 -> 46360 | C19: ='Driver Build'!R5 -> Forecast | D19: ='Live Model'!N19 -> 3257387.7 | E19: =Assumptions!$C$28 -> 1200000 | F19: ='Live Model'!N8 -> 775676.51 | G19: ='Live Model'!N16 -> 1042256.6 | H19: ='Live Model'!N18 -> -266580.09
A20: W17 | B20: ='Driver Build'!S4 -> 46367 | C20: ='Driver Build'!S5 -> Forecast | D20: ='Live Model'!O19 -> 3440602.9 | E20: =Assumptions!$C$28 -> 1200000 | F20: ='Live Model'!O8 -> 778228.23 | G20: ='Live Model'!O16 -> 595012.99 | H20: ='Live Model'!O18 -> 183215.24
A23: Week | B23: Best | C23: Base | D23: Worst | E23: Min Covenant
A24: W4 | B24: =Actuals!$F$19 -> 3267000 | C24: =Actuals!$F$19 -> 3267000 | D24: =Actuals!$F$19 -> 3267000 | E24: =Assumptions!$C$28 -> 1200000
A25: W5 | B25: =Scenario!C15 -> 3604782.7 | C25: =Scenario!C24 -> 3531721.5 | D25: =Scenario!C33 -> 3420806.2 | E25: =Assumptions!$C$28 -> 1200000
A26: W6 | B26: =Scenario!D15 -> 3639124.3 | C26: =Scenario!D24 -> 3482525.9 | D26: =Scenario!D33 -> 3246550.6 | E26: =Assumptions!$C$28 -> 1200000
A27: W7 | B27: =Scenario!E15 -> 3752714.2 | C27: =Scenario!E24 -> 3513972.5 | D27: =Scenario!E33 -> 3154625 | E27: =Assumptions!$C$28 -> 1200000
A28: W8 | B28: =Scenario!F15 -> 3795279 | C28: =Scenario!F24 -> 3471299.5 | D28: =Scenario!F33 -> 2984308.9 | E28: =Assumptions!$C$28 -> 1200000
A29: W9 | B29: =Scenario!G15 -> 4149503.9 | C29: =Scenario!G24 -> 3749326.5 | D29: =Scenario!G33 -> 3146648.8 | E29: =Assumptions!$C$28 -> 1200000
A30: W10 | B30: =Scenario!H15 -> 4117154.9 | C30: =Scenario!H24 -> 3628213.1 | D30: =Scenario!H33 -> 2892994.3 | E30: =Assumptions!$C$28 -> 1200000
A31: W11 | B31: =Scenario!I15 -> 4292691.1 | C31: =Scenario!I24 -> 3722143.3 | D31: =Scenario!I33 -> 2864045.9 | E31: =Assumptions!$C$28 -> 1200000
A32: W12 | B32: =Scenario!J15 -> 4012687.2 | C32: =Scenario!J24 -> 3348934.4 | D32: =Scenario!J33 -> 2352895.6 | E32: =Assumptions!$C$28 -> 1200000
A33: W13 | B33: =Scenario!K15 -> 4321771.9 | C33: =Scenario!K24 -> 3586448 | D33: =Scenario!K33 -> 2481865 | E33: =Assumptions!$C$28 -> 1200000
A34: W14 | B34: =Scenario!L15 -> 4154748.2 | C34: =Scenario!L24 -> 3337296.3 | D34: =Scenario!L33 -> 2110766.9 | E34: =Assumptions!$C$28 -> 1200000
A35: W15 | B35: =Scenario!M15 -> 4404772.3 | C35: =Scenario!M24 -> 3523967.7 | D35: =Scenario!M33 -> 2201476.1 | E35: =Assumptions!$C$28 -> 1200000
A36: W16 | B36: =Scenario!N15 -> 4208243.7 | C36: =Scenario!N24 -> 3257387.7 | D36: =Scenario!N33 -> 1831151.7 | E36: =Assumptions!$C$28 -> 1200000
A37: W17 | B37: =Scenario!O15 -> 4448220.7 | C37: =Scenario!O24 -> 3440602.9 | D37: =Scenario!O33 -> 1928308.1 | E37: =Assumptions!$C$28 -> 1200000
A39: Week | B39: AP Payments | C39: Payroll | D39: Opex | E39: Capex | F39: Debt Service | G39: Taxes
A40: W5 | B40: ='Live Model'!C10 -> 631813.61 | C40: ='Live Model'!C11 -> 0 | D40: ='Live Model'!C12 -> 95000 | E40: ='Live Model'!C13 -> 0 | F40: ='Live Model'!C14 -> 21000 | G40: ='Live Model'!C15 -> 0
A41: W6 | B41: ='Live Model'!D10 -> 640963.36 | C41: ='Live Model'!D11 -> 318000 | D41: ='Live Model'!D12 -> 95000 | E41: ='Live Model'!D13 -> 0 | F41: ='Live Model'!D14 -> 21000 | G41: ='Live Model'!D15 -> 0
A42: W7 | B42: ='Live Model'!E10 -> 651136.93 | C42: ='Live Model'!E11 -> 0 | D42: ='Live Model'!E12 -> 95000 | E42: ='Live Model'!E13 -> 240000 | F42: ='Live Model'!E14 -> 21000 | G42: ='Live Model'!E15 -> 0
A43: W8 | B43: ='Live Model'!F10 -> 658141.95 | C43: ='Live Model'!F11 -> 318000 | D43: ='Live Model'!F12 -> 95000 | E43: ='Live Model'!F13 -> 0 | F43: ='Live Model'!F14 -> 21000 | G43: ='Live Model'!F15 -> 0
A44: W9 | B44: ='Live Model'!G10 -> 662707.54 | C44: ='Live Model'!G11 -> 0 | D44: ='Live Model'!G12 -> 95000 | E44: ='Live Model'!G13 -> 0 | F44: ='Live Model'!G14 -> 21000 | G44: ='Live Model'!G15 -> 0
...
